Workbook

Sheet How to use
A1: EMO Tracker evaluation scoring sheet
A3: Each user does three things in one session: the usability test, then the SUS, then the ISO/IEC 25010 questionnaire. Give all three forms the same Respondent No.
A5: 1. Usability test tab (Table 4.6): copy each task sheet's Completed, Time (s) and Easy to do answers into the task's row.
A6: 2. SUS tab (Table 4.8): type each SUS form's 10 answers in one row. The score (0 to 100) and the comparison with 68 appear by themselves.
A7: 3. ISO ratings tab: type each ISO form's 22 answers in its column (R1 = form 1). The Table 4.7 tab fills itself, with the bar chart for Figure 4.27.
A8: 4. Respondents tab: type each ISO form's Part I answers.
A9: 5. Comments tab: type the ISO Part III answers and the usability test's closing answers word for word, then give each a category.
A10: 6. Check every number against the paper forms before copying anything into the paper.
A12: Legend: yellow cells = type here. Every other cell is a formula; don't type over it.
A13: Example (not real data): if forms 1, 2 and 3 rated ISO statement 1 as 5, 4 and 5, type 5, 4, 5 in D5, E5 and F5 of the ISO ratings tab. The mean shows 4.67 (Excellent).
A15: The interpretation scale and its labels are on the Scale tab. Confirm the labels with the adviser before using them in the paper.

Sheet Usability test
A1: Usability test (Table 4.6 draft): copy each task sheet's results into the yellow cells
A2: Completed: pick Yes, With help or No. Time: in seconds (1 min 30 s = 90). Easy to do: the number the user gave (1 to 5).
A4: No. | B4: Role | C4: Task | D4: Respondent No. | E4: Completed | F4: Time (s) | G4: Easy to do (1-5) | H4: Interpretation
A5: 1 | B5: Administrator | C5: Log in as the Administrator | H5: =IF(G5="","",INDEX(Scale!$D$5:$D$9,MATCH(G5,Scale!$A$5:$A$9,1)))
A6: 2 | B6: Administrator | C6: Add the Research Colloquium (internal event) | H6: =IF(G6="","",INDEX(Scale!$D$5:$D$9,MATCH(G6,Scale!$A$5:$A$9,1)))
A7: 3 | B7: Administrator | C7: Add an overlapping booking at PSB MPH | H7: =IF(G7="","",INDEX(Scale!$D$5:$D$9,MATCH(G7,Scale!$A$5:$A$9,1)))
A8: 4 | B8: Administrator | C8: Move the Research Colloquium one week later (rescheduled) | H8: =IF(G8="","",INDEX(Scale!$D$5:$D$9,MATCH(G8,Scale!$A$5:$A$9,1)))
A9: 5 | B9: Administrator | C9: Cancel, then restore the Research Colloquium | H9: =IF(G9="","",INDEX(Scale!$D$5:$D$9,MATCH(G9,Scale!$A$5:$A$9,1)))
A10: 6 | B10: Administrator | C10: Add the venue PSB Room 305 | H10: =IF(G10="","",INDEX(Scale!$D$5:$D$9,MATCH(G10,Scale!$A$5:$A$9,1)))
A11: 7 | B11: Administrator | C11: Create, then deactivate a Staff account | H11: =IF(G11="","",INDEX(Scale!$D$5:$D$9,MATCH(G11,Scale!$A$5:$A$9,1)))
A12: 8 | B12: Officer | C12: Add three tasks to the Inter-College Quiz Bee | H12: =IF(G12="","",INDEX(Scale!$D$5:$D$9,MATCH(G12,Scale!$A$5:$A$9,1)))
A13: 9 | B13: Officer | C13: Upload, then download a PDF | H13: =IF(G13="","",INDEX(Scale!$D$5:$D$9,MATCH(G13,Scale!$A$5:$A$9,1)))
A14: 10 | B14: Officer | C14: Download an event's PDF report | H14: =IF(G14="","",INDEX(Scale!$D$5:$D$9,MATCH(G14,Scale!$A$5:$A$9,1)))
A15: 11 | B15: Officer | C15: Find this month's completed events on Analytics | H15: =IF(G15="","",INDEX(Scale!$D$5:$D$9,MATCH(G15,Scale!$A$5:$A$9,1)))
A16: 12 | B16: Officer | C16: Try to change a task of a completed event | H16: =IF(G16="","",INDEX(Scale!$D$5:$D$9,MATCH(G16,Scale!$A$5:$A$9,1)))
... A21: 17 | B21: Staff | C21: Change own password | H21: =IF(G21="","",INDEX(Scale!$D$5:$D$9,MATCH(G21,Scale!$A$5:$A$9,1)))
A23: Summary by role
A24: Role | B24: Tasks | C24: Recorded | D24: Completed without help | E24: Completed with help | F24: Not completed | G24: Average time (s) | H24: Average ease | I24: Interpretation
A25: Administrator | B25: 7 | C25: =COUNTA(E5:E11) | D25: =COUNTIF(E5:E11,"Yes") | E25: =COUNTIF(E5:E11,"With help") | F25: =COUNTIF(E5:E11,"No") | G25: =IFERROR(ROUND(AVERAGE(F5:F11),0),"") | H25: =IFERROR(ROUND(AVERAGE(G5:G11),2),"") | I25: =IF(H25="","",INDEX(Scale!$D$5:$D$9,MATCH(H25,Scale!$A$5:$A$9,1)))
A26: Officer | B26: 6 | C26: =COUNTA(E12:E17) | D26: =COUNTIF(E12:E17,"Yes") | E26: =COUNTIF(E12:E17,"With help") | F26: =COUNTIF(E12:E17,"No") | G26: =IFERROR(ROUND(AVERAGE(F12:F17),0),"") | H26: =IFERROR(ROUND(AVERAGE(G12:G17),2),"") | I26: =IF(H26="","",INDEX(Scale!$D$5:$D$9,MATCH(H26,Scale!$A$5:$A$9,1)))
A27: Staff | B27: 4 | C27: =COUNTA(E18:E21) | D27: =COUNTIF(E18:E21,"Yes") | E27: =COUNTIF(E18:E21,"With help") | F27: =COUNTIF(E18:E21,"No") | G27: =IFERROR(ROUND(AVERAGE(F18:F21),0),"") | H27: =IFERROR(ROUND(AVERAGE(G18:G21),2),"") | I27: =IF(H27="","",INDEX(Scale!$D$5:$D$9,MATCH(H27,Scale!$A$5:$A$9,1)))
A28: All tasks | B28: =SUM(B25:B27) | C28: =SUM(C25:C27) | D28: =SUM(D25:D27) | E28: =SUM(E25:E27) | F28: =SUM(F25:F27) | G28: =IFERROR(ROUND(AVERAGE(F5:F21),0),"") | H28: =IFERROR(ROUND(AVERAGE(G5:G21),2),"") | I28: =IF(H28="","",INDEX(Scale!$D$5:$D$9,MATCH(H28,Scale!$A$5:$A$9,1)))
A30: Completion rate without help | D30: =IF(C28=0,"",D28/C28)
A31: Completion rate with or without help | D31: =IF(C28=0,"",(D28+E28)/C28)
A32: Rates are out of the tasks recorded. Average time uses only the tasks with a time written.

Sheet SUS
A1: System Usability Scale (Table 4.8 draft): type each form's answers (1 to 5)
A2: One row per form. The score appears only when all 10 statements are answered. Do not reverse the even statements yourself; the formula does it.
A4: Respondent No. | B4: Role | C4: Q1 | D4: Q2 | E4: Q3 | F4: Q4 | G4: Q5 | H4: Q6 | I4: Q7 | J4: Q8 | K4: Q9 | L4: Q10 | M4: Answered | N4: SUS score (0-100)
A5: 1 | M5: =COUNT(C5:L5) | N5: =IF(M5<10,"",2.5*((C5-1)+(E5-1)+(G5-1)+(I5-1)+(K5-1)+(5-D5)+(5-F5)+(5-H5)+(5-J5)+(5-L5)))
A6: 2 | M6: =COUNT(C6:L6) | N6: =IF(M6<10,"",2.5*((C6-1)+(E6-1)+(G6-1)+(I6-1)+(K6-1)+(5-D6)+(5-F6)+(5-H6)+(5-J6)+(5-L6)))
A7: 3 | M7: =COUNT(C7:L7) | N7: =IF(M7<10,"",2.5*((C7-1)+(E7-1)+(G7-1)+(I7-1)+(K7-1)+(5-D7)+(5-F7)+(5-H7)+(5-J7)+(5-L7)))
A8: 4 | M8: =COUNT(C8:L8) | N8: =IF(M8<10,"",2.5*((C8-1)+(E8-1)+(G8-1)+(I8-1)+(K8-1)+(5-D8)+(5-F8)+(5-H8)+(5-J8)+(5-L8)))
A9: 5 | M9: =COUNT(C9:L9) | N9: =IF(M9<10,"",2.5*((C9-1)+(E9-1)+(G9-1)+(I9-1)+(K9-1)+(5-D9)+(5-F9)+(5-H9)+(5-J9)+(5-L9)))
A11: Average SUS score | N11: =IFERROR(ROUND(AVERAGE(N5:N9),1),"")
A12: Benchmark (average SUS score) | N12: 68
A13: Compared with the benchmark | N13: =IF(N11="","",IF(N11>N12,"Above average",IF(N11=N12,"Average","Below average")))
A15: Score per form = 2.5 x [ (Q1-1)+(Q3-1)+(Q5-1)+(Q7-1)+(Q9-1) + (5-Q2)+(5-Q4)+(5-Q6)+(5-Q8)+(5-Q10) ]. The benchmark of 68 is the commonly cited average SUS score (see Hyzy et al., 2022, already in Chapter 2). Source of the scale: Brooke (1996).

Sheet ISO ratings
A1: ISO/IEC 25010 ratings: type each respondent's answer (1 to 5) in the yellow cells
A2: One column per respondent, in the order of the Respondent No. on the forms. Leave a cell empty if the statement was not answered.
A4: No. | B4: Characteristic | C4: Statement | D4: R1 | E4: R2 | F4: R3 | G4: R4 | H4: R5 | I4: n | J4: f (5) | K4: f (4) | L4: f (3) | M4: f (2) | N4: f (1) | O4: Weighted mean | P4: Interpretation
A5: 1 | B5: Functional Suitability | C5: EMO Tracker has the features I need to keep the EMO's schedule and prepare its events. | I5: =COUNT(D5:H5) | J5: =COUNTIF(D5:H5,5) | K5: =COUNTIF(D5:H5,4) | L5: =COUNTIF(D5:H5,3) | M5: =COUNTIF(D5:H5,2) | N5: =COUNTIF(D5:H5,1) | O5: =IF(I5=0,"",ROUND((5*J5+4*K5+3*L5+2*M5+1*N5)/I5,2)) | P5: =IF(O5="","",INDEX(Scale!$D$5:$D$9,MATCH(O5,Scale!$A$5:$A$9,1)))
A6: 2 | B6: Functional Suitability | C6: The system saves and shows event, venue, and task details correctly. | I6: =COUNT(D6:H6) | J6: =COUNTIF(D6:H6,5) | K6: =COUNTIF(D6:H6,4) | L6: =COUNTIF(D6:H6,3) | M6: =COUNTIF(D6:H6,2) | N6: =COUNTIF(D6:H6,1) | O6: =IF(I6=0,"",ROUND((5*J6+4*K6+3*L6+2*M6+1*N6)/I6,2)) | P6: =IF(O6="","",INDEX(Scale!$D$5:$D$9,MATCH(O6,Scale!$A$5:$A$9,1)))
A7: 3 | B7: Functional Suitability | C7: The readiness label and its reason match how prepared an event really is. | I7: =COUNT(D7:H7) | J7: =COUNTIF(D7:H7,5) | K7: =COUNTIF(D7:H7,4) | L7: =COUNTIF(D7:H7,3) | M7: =COUNTIF(D7:H7,2) | N7: =COUNTIF(D7:H7,1) | O7: =IF(I7=0,"",ROUND((5*J7+4*K7+3*L7+2*M7+1*N7)/I7,2)) | P7: =IF(O7="","",INDEX(Scale!$D$5:$D$9,MATCH(O7,Scale!$A$5:$A$9,1)))
A8: 4 | B8: Performance Efficiency | C8: Pages open quickly on the device I use. | I8: =COUNT(D8:H8) | J8: =COUNTIF(D8:H8,5) | K8: =COUNTIF(D8:H8,4) | L8: =COUNTIF(D8:H8,3) | M8: =COUNTIF(D8:H8,2) | N8: =COUNTIF(D8:H8,1) | O8: =IF(I8=0,"",ROUND((5*J8+4*K8+3*L8+2*M8+1*N8)/I8,2)) | P8: =IF(O8="","",INDEX(Scale!$D$5:$D$9,MATCH(O8,Scale!$A$5:$A$9,1)))
A9: 5 | B9: Performance Efficiency | C9: Saving an event, a task, or a status change takes only a moment. | I9: =COUNT(D9:H9) | J9: =COUNTIF(D9:H9,5) | K9: =COUNTIF(D9:H9,4) | L9: =COUNTIF(D9:H9,3) | M9: =COUNTIF(D9:H9,2) | N9: =COUNTIF(D9:H9,1) | O9: =IF(I9=0,"",ROUND((5*J9+4*K9+3*L9+2*M9+1*N9)/I9,2)) | P9: =IF(O9="","",INDEX(Scale!$D$5:$D$9,MATCH(O9,Scale!$A$5:$A$9,1)))
A10: 6 | B10: Performance Efficiency | C10: The system stays fast when other EMO members use it at the same time. | I10: =COUNT(D10:H10) | J10: =COUNTIF(D10:H10,5) | K10: =COUNTIF(D10:H10,4) | L10: =COUNTIF(D10:H10,3) | M10: =COUNTIF(D10:H10,2) | N10: =COUNTIF(D10:H10,1) | O10: =IF(I10=0,"",ROUND((5*J10+4*K10+3*L10+2*M10+1*N10)/I10,2)) | P10: =IF(O10="","",INDEX(Scale!$D$5:$D$9,MATCH(O10,Scale!$A$5:$A$9,1)))
A11: 7 | B11: Compatibility | C11: The system works well while other applications are open on my device. | I11: =COUNT(D11:H11) | J11: =COUNTIF(D11:H11,5) | K11: =COUNTIF(D11:H11,4) | L11: =COUNTIF(D11:H11,3) | M11: =COUNTIF(D11:H11,2) | N11: =COUNTIF(D11:H11,1) | O11: =IF(I11=0,"",ROUND((5*J11+4*K11+3*L11+2*M11+1*N11)/I11,2)) | P11: =IF(O11="","",INDEX(Scale!$D$5:$D$9,MATCH(O11,Scale!$A$5:$A$9,1)))
A12: 8 | B12: Compatibility | C12: The exported Excel or CSV file opens correctly in Excel or Google Sheets. | I12: =COUNT(D12:H12) | J12: =COUNTIF(D12:H12,5) | K12: =COUNTIF(D12:H12,4) | L12: =COUNTIF(D12:H12,3) | M12: =COUNTIF(D12:H12,2) | N12: =COUNTIF(D12:H12,1) | O12: =IF(I12=0,"",ROUND((5*J12+4*K12+3*L12+2*M12+1*N12)/I12,2)) | P12: =IF(O12="","",INDEX(Scale!$D$5:$D$9,MATCH(O12,Scale!$A$5:$A$9,1)))
A13: 9 | B13: Compatibility | C13: The PDF event report opens and prints correctly. | I13: =COUNT(D13:H13) | J13: =COUNTIF(D13:H13,5) | K13: =COUNTIF(D13:H13,4) | L13: =COUNTIF(D13:H13,3) | M13: =COUNTIF(D13:H13,2) | N13: =COUNTIF(D13:H13,1) | O13: =IF(I13=0,"",ROUND((5*J13+4*K13+3*L13+2*M13+1*N13)/I13,2)) | P13: =IF(O13="","",INDEX(Scale!$D$5:$D$9,MATCH(O13,Scale!$A$5:$A$9,1)))
A14: 10 | B14: Interaction Capability (Usability) | C14: When I first used the system, I could tell what each page is for. | I14: =COUNT(D14:H14) | J14: =COUNTIF(D14:H14,5) | K14: =COUNTIF(D14:H14,4) | L14: =COUNTIF(D14:H14,3) | M14: =COUNTIF(D14:H14,2) | N14: =COUNTIF(D14:H14,1) | O14: =IF(I14=0,"",ROUND((5*J14+4*K14+3*L14+2*M14+1*N14)/I14,2)) | P14: =IF(O14="","",INDEX(Scale!$D$5:$D$9,MATCH(O14,Scale!$A$5:$A$9,1)))
A15: 11 | B15: Interaction Capability (Usability) | C15: I learned to use the system without needing much help. | I15: =COUNT(D15:H15) | J15: =COUNTIF(D15:H15,5) | K15: =COUNTIF(D15:H15,4) | L15: =COUNTIF(D15:H15,3) | M15: =COUNTIF(D15:H15,2) | N15: =COUNTIF(D15:H15,1) | O15: =IF(I15=0,"",ROUND((5*J15+4*K15+3*L15+2*M15+1*N15)/I15,2)) | P15: =IF(O15="","",INDEX(Scale!$D$5:$D$9,MATCH(O15,Scale!$A$5:$A$9,1)))
A16: 12 | B16: Interaction Capability (Usability) | C16: The buttons, menus, and labels are clear and easy to use. | I16: =COUNT(D16:H16) | J16: =COUNTIF(D16:H16,5) | K16: =COUNTIF(D16:H16,4) | L16: =COUNTIF(D16:H16,3) | M16: =COUNTIF(D16:H16,2) | N16: =COUNTIF(D16:H16,1) | O16: =IF(I16=0,"",ROUND((5*J16+4*K16+3*L16+2*M16+1*N16)/I16,2)) | P16: =IF(O16="","",INDEX(Scale!$D$5:$D$9,MATCH(O16,Scale!$A$5:$A$9,1)))
... A26: 22 | B26: Flexibility | C26: I can use the system on different devices without installing anything. | I26: =COUNT(D26:H26) | J26: =COUNTIF(D26:H26,5) | K26: =COUNTIF(D26:H26,4) | L26: =COUNTIF(D26:H26,3) | M26: =COUNTIF(D26:H26,2) | N26: =COUNTIF(D26:H26,1) | O26: =IF(I26=0,"",ROUND((5*J26+4*K26+3*L26+2*M26+1*N26)/I26,2)) | P26: =IF(O26="","",INDEX(Scale!$D$5:$D$9,MATCH(O26,Scale!$A$5:$A$9,1)))
A28: Weighted mean = (5 x f5 + 4 x f4 + 3 x f3 + 2 x f2 + 1 x f1) / n, where f is how many respondents gave that rating and n is how many answered.

Sheet Table 4.7
A1: Table 4.7 (draft): ISO/IEC 25010 evaluation results
A2: Fills itself from the ISO ratings sheet. Copy the table into the paper; don't type in this sheet.
A4: Characteristic and statements | B4: Mean | C4: Interpretation
A5: Functional Suitability | B5: =IFERROR(ROUND(AVERAGE('ISO ratings'!O5:O7),2),"") | C5: =IF(B5="","",INDEX(Scale!$D$5:$D$9,MATCH(B5,Scale!$A$5:$A$9,1)))
A6: ='ISO ratings'!A5&". "&'ISO ratings'!C5 | B6: ='ISO ratings'!O5 | C6: ='ISO ratings'!P5
A7: ='ISO ratings'!A6&". "&'ISO ratings'!C6 | B7: ='ISO ratings'!O6 | C7: ='ISO ratings'!P6
A8: ='ISO ratings'!A7&". "&'ISO ratings'!C7 | B8: ='ISO ratings'!O7 | C8: ='ISO ratings'!P7
A9: Performance Efficiency | B9: =IFERROR(ROUND(AVERAGE('ISO ratings'!O8:O10),2),"") | C9: =IF(B9="","",INDEX(Scale!$D$5:$D$9,MATCH(B9,Scale!$A$5:$A$9,1)))
A10: ='ISO ratings'!A8&". "&'ISO ratings'!C8 | B10: ='ISO ratings'!O8 | C10: ='ISO ratings'!P8
A11: ='ISO ratings'!A9&". "&'ISO ratings'!C9 | B11: ='ISO ratings'!O9 | C11: ='ISO ratings'!P9
A12: ='ISO ratings'!A10&". "&'ISO ratings'!C10 | B12: ='ISO ratings'!O10 | C12: ='ISO ratings'!P10
A13: Compatibility | B13: =IFERROR(ROUND(AVERAGE('ISO ratings'!O11:O13),2),"") | C13: =IF(B13="","",INDEX(Scale!$D$5:$D$9,MATCH(B13,Scale!$A$5:$A$9,1)))
A14: ='ISO ratings'!A11&". "&'ISO ratings'!C11 | B14: ='ISO ratings'!O11 | C14: ='ISO ratings'!P11
A15: ='ISO ratings'!A12&". "&'ISO ratings'!C12 | B15: ='ISO ratings'!O12 | C15: ='ISO ratings'!P12
A16: ='ISO ratings'!A13&". "&'ISO ratings'!C13 | B16: ='ISO ratings'!O13 | C16: ='ISO ratings'!P13
A17: Interaction Capability (Usability) | B17: =IFERROR(ROUND(AVERAGE('ISO ratings'!O14:O17),2),"") | C17: =IF(B17="","",INDEX(Scale!$D$5:$D$9,MATCH(B17,Scale!$A$5:$A$9,1)))
A18: ='ISO ratings'!A14&". "&'ISO ratings'!C14 | B18: ='ISO ratings'!O14 | C18: ='ISO ratings'!P14
A19: ='ISO ratings'!A15&". "&'ISO ratings'!C15 | B19: ='ISO ratings'!O15 | C19: ='ISO ratings'!P15
A20: ='ISO ratings'!A16&". "&'ISO ratings'!C16 | B20: ='ISO ratings'!O16 | C20: ='ISO ratings'!P16
A21: ='ISO ratings'!A17&". "&'ISO ratings'!C17 | B21: ='ISO ratings'!O17 | C21: ='ISO ratings'!P17
A22: Reliability | B22: =IFERROR(ROUND(AVERAGE('ISO ratings'!O18:O20),2),"") | C22: =IF(B22="","",INDEX(Scale!$D$5:$D$9,MATCH(B22,Scale!$A$5:$A$9,1)))
A23: ='ISO ratings'!A18&". "&'ISO ratings'!C18 | B23: ='ISO ratings'!O18 | C23: ='ISO ratings'!P18
A24: ='ISO ratings'!A19&". "&'ISO ratings'!C19 | B24: ='ISO ratings'!O19 | C24: ='ISO ratings'!P19
A25: ='ISO ratings'!A20&". "&'ISO ratings'!C20 | B25: ='ISO ratings'!O20 | C25: ='ISO ratings'!P20
A26: Security | B26: =IFERROR(ROUND(AVERAGE('ISO ratings'!O21:O23),2),"") | C26: =IF(B26="","",INDEX(Scale!$D$5:$D$9,MATCH(B26,Scale!$A$5:$A$9,1)))
A27: ='ISO ratings'!A21&". "&'ISO ratings'!C21 | B27: ='ISO ratings'!O21 | C27: ='ISO ratings'!P21
A28: ='ISO ratings'!A22&". "&'ISO ratings'!C22 | B28: ='ISO ratings'!O22 | C28: ='ISO ratings'!P22
A29: ='ISO ratings'!A23&". "&'ISO ratings'!C23 | B29: ='ISO ratings'!O23 | C29: ='ISO ratings'!P23
A30: Flexibility | B30: =IFERROR(ROUND(AVERAGE('ISO ratings'!O24:O26),2),"") | C30: =IF(B30="","",INDEX(Scale!$D$5:$D$9,MATCH(B30,Scale!$A$5:$A$9,1)))
A31: ='ISO ratings'!A24&". "&'ISO ratings'!C24 | B31: ='ISO ratings'!O24 | C31: ='ISO ratings'!P24
A32: ='ISO ratings'!A25&". "&'ISO ratings'!C25 | B32: ='ISO ratings'!O25 | C32: ='ISO ratings'!P25
A33: ='ISO ratings'!A26&". "&'ISO ratings'!C26 | B33: ='ISO ratings'!O26 | C33: ='ISO ratings'!P26
A34: Overall mean | B34: =IFERROR(ROUND(AVERAGE(B5,B9,B13,B17,B22,B26,B30),2),"") | C34: =IF(B34="","",INDEX(Scale!$D$5:$D$9,MATCH(B34,Scale!$A$5:$A$9,1)))
A36: A characteristic's mean is the average of its statements' means. The overall mean is the average of the seven characteristic means.
E39: Chart data | F39: Mean
E40: Functional Suitability | F40: =B5
E41: Performance Efficiency | F41: =B9
E42: Compatibility | F42: =B13
E43: Interaction Capability (Usability) | F43: =B17
E44: Reliability | F44: =B22
...

Sheet Respondents
A1: Respondent profile (Part I of the ISO/IEC 25010 questionnaire)
A2: One row per respondent. Type x for each device the respondent checked.
A4: Respondent No. | B4: Role | C4: Laptop or computer | D4: Phone | E4: Tablet | F4: Days used
A5: 1
A6: 2
A7: 3
A8: 4
A9: 5
A11: Role | B11: Frequency | C11: Percentage
A12: Administrator | B12: =COUNTIF($B$5:$B$9,A12) | C12: =IF($B$15=0,"",B12/$B$15)
A13: Officer | B13: =COUNTIF($B$5:$B$9,A13) | C13: =IF($B$15=0,"",B13/$B$15)
A14: Staff | B14: =COUNTIF($B$5:$B$9,A14) | C14: =IF($B$15=0,"",B14/$B$15)
A15: Total | B15: =SUM(B12:B14) | C15: =IF(B15=0,"",SUM(C12:C14))
A17: Device | B17: Frequency | C17: Percentage
A18: Laptop or computer | B18: =COUNTIF($C$5:$C$9,"x") | C18: =IF($B$15=0,"",B18/$B$15)
A19: Phone | B19: =COUNTIF($D$5:$D$9,"x") | C19: =IF($B$15=0,"",B19/$B$15)
A20: Tablet | B20: =COUNTIF($E$5:$E$9,"x") | C20: =IF($B$15=0,"",B20/$B$15)
A22: Device percentages are out of all respondents; one person can check more than one device.
A24: Average days used | B24: =IFERROR(ROUND(AVERAGE(F5:F9),1),"")

Sheet Comments
A1: Comments (ISO questionnaire Part III and the usability test's closing questions)
A2: Type each answer word for word. Give it a category (for example Ease of use, Speed, Missing feature, Problem) to find the patterns.
A4: Respondent No. | B4: Question | C4: Answer (word for word) | D4: Category

Sheet Scale
A1: Interpretation scale (5-point)
A2: Means are rounded to 2 decimals, then read from this table. Confirm the labels with the adviser; changing columns C and D updates every sheet.
A4: From | B4: To | C4: Description | D4: Interpretation
A5: 1 | B5: 1.8 | C5: Strongly Disagree | D5: Poor
A6: 1.81 | B6: 2.6 | C6: Disagree | D6: Fair
A7: 2.61 | B7: 3.4 | C7: Neutral | D7: Good
A8: 3.41 | B8: 4.2 | C8: Agree | D8: Very Good
A9: 4.21 | B9: 5 | C9: Strongly Agree | D9: Excellent
